<?xml version="1.0"?>
<sdf version='1.6'>
  <model name='mav_isir'>
    <!-- mav_isir body -->
    <link name='base_link'>
      <pose>0 0 0 0 0 0</pose>
      <inertial>
        <pose>0 0 0 0 0 0</pose>
        <mass>1.5</mass>
        <inertia>
          <ixx>0.011</ixx>
          <ixy>0</ixy>
          <ixz>0</ixz>
          <iyy>0.015</iyy>
          <iyz>0</iyz>
          <izz>0.021</izz>
        </inertia>
      </inertial>
      <collision name='base_link_collision'>
        <pose>0 0 0.1 0 -0 -1.57</pose>
        <geometry>
          <box>
            <size>0.32 0.32 0.2</size>
          </box>
        </geometry>
        <surface>
          <contact>
            <ode>
              <min_depth>0.001</min_depth>
              <max_vel>0</max_vel>
            </ode>
          </contact>
          <friction>
            <ode/>
          </friction>
        </surface>
      </collision>
      <visual name='base_link_visual'>
        <pose>0 0 0 0 0 0</pose>
        <geometry>
          <mesh>
            <scale>1 1 1</scale>
            <uri>model://mav_isir/meshes/body.STL</uri>
          </mesh>
        </geometry>
        <material>
          <script>
            <name>Gazebo/DarkGrey</name>
            <uri>file://media/materials/scripts/gazebo.material</uri>
          </script>
        </material>
      </visual>
      <gravity>1</gravity>
      <velocity_decay/>
    </link>

<!--*********************************** rotor_0 *********************************-->
    <link name='rotor_0'>
      <pose>0.078 -0.1 0 0 0 0</pose>
      <inertial>
        <pose>0 -0 0 0 -0 0</pose>
        <mass>0.005</mass>
        <inertia>
          <ixx>9.75e-07</ixx>
          <ixy>0</ixy>
          <ixz>0</ixz>
          <iyy>0.000273104</iyy>
          <iyz>0</iyz>
          <izz>0.000274004</izz>
        </inertia>
      </inertial>
      <collision name='rotor_0_collision'>
        <pose>0 0 0.076 0 -0 0</pose>
        <geometry>
          <cylinder>
            <length>0.01</length>
            <radius>0.064</radius>
          </cylinder>
        </geometry>
        <surface>
          <contact>
            <ode/>
          </contact>
          <friction>
            <ode/>
          </friction>
        </surface>
      </collision>
      <visual name='rotor_0_visual'>
        <pose>0 0 0.076 0 -0 0</pose>
        <geometry>
          <mesh>
            <scale>1 1 1</scale>
            <uri>model://mav_isir/meshes/propeller1.STL</uri>
          </mesh>
        </geometry>
        <material>
          <script>
            <name>Gazebo/Wood</name>
            <uri>file://media/materials/scripts/gazebo.material</uri>
          </script>
        </material>
      </visual>
      <gravity>1</gravity>
      <velocity_decay/>
      <self_collide>0</self_collide>
    </link>
    <joint name='rotor_0_joint' type='revolute'>
      <child>rotor_0</child>
      <parent>base_link</parent>
      <axis>
        <xyz>0 0 1</xyz>
        <limit>
          <lower>-1e+16</lower>
          <upper>1e+16</upper>
        </limit>
        <dynamics>
          <spring_reference>0</spring_reference>
          <spring_stiffness>0</spring_stiffness>
        </dynamics>
        <use_parent_model_frame>1</use_parent_model_frame>
      </axis>
    </joint>
<!--*********************************** rotor_1 *********************************-->
    <link name='rotor_1'>
      <pose>-0.078 0.1 0 0 -0 0</pose>
      <inertial>
        <pose>0 -0 0 0 -0 0</pose>
        <mass>0.005</mass>
        <inertia>
          <ixx>9.75e-07</ixx>
          <ixy>0</ixy>
          <ixz>0</ixz>
          <iyy>0.000273104</iyy>
          <iyz>0</iyz>
          <izz>0.000274004</izz>
        </inertia>
      </inertial>
      <collision name='rotor_1_collision'>
        <pose>0 0 0.076 0 -0 0</pose>
        <geometry>
          <cylinder>
            <length>0.01</length>
            <radius>0.064</radius>
          </cylinder>
        </geometry>
        <surface>
          <contact>
            <ode/>
          </contact>
          <friction>
            <ode/>
          </friction>
        </surface>
      </collision>
      <visual name='rotor_1_visual'>
        <pose>0 0 0.076 0 -0 0</pose>
        <geometry>
          <mesh>
            <scale>1 1 1</scale>
            <uri>model://mav_isir/meshes/propeller2.STL</uri>
          </mesh>
        </geometry>
        <material>
          <script>
            <name>Gazebo/Wood</name>
            <uri>file://media/materials/scripts/gazebo.material</uri>
          </script>
        </material>
      </visual>
      <gravity>1</gravity>
      <velocity_decay/>
      <self_collide>0</self_collide>
    </link>
    <joint name='rotor_1_joint' type='revolute'>
      <child>rotor_1</child>
      <parent>base_link</parent>
      <axis>
        <xyz>0 0 1</xyz>
        <limit>
          <lower>-1e+16</lower>
          <upper>1e+16</upper>
        </limit>
        <dynamics>
          <spring_reference>0</spring_reference>
          <spring_stiffness>0</spring_stiffness>
        </dynamics>
        <use_parent_model_frame>1</use_parent_model_frame>
      </axis>
    </joint>
<!--*********************************** rotor_2 *********************************-->
    <link name='rotor_2'>
      <pose>0.078 0.1 0 0 0 0</pose>
      <inertial>
        <pose>0 0 0 0 -0 0</pose>
        <mass>0.005</mass>
        <inertia>
          <ixx>9.75e-07</ixx>
          <ixy>0</ixy>
          <ixz>0</ixz>
          <iyy>0.000273104</iyy>
          <iyz>0</iyz>
          <izz>0.000274004</izz>
        </inertia>
      </inertial>
      <collision name='rotor_2_collision'>
        <pose>0 0 0.076 0 -0 0</pose>
        <geometry>
          <cylinder>
            <length>0.01</length>
            <radius>0.064</radius>
          </cylinder>
        </geometry>
        <surface>
          <contact>
            <ode/>
          </contact>
          <friction>
            <ode/>
          </friction>
        </surface>
      </collision>
      <visual name='rotor_2_visual'>
        <pose>0 0 0.076 0 -0 0</pose>
        <geometry>
          <mesh>
            <scale>1 1 1</scale>
            <uri>model://mav_isir/meshes/propeller3.STL</uri>
          </mesh>
        </geometry>
        <material>
          <script>
            <name>Gazebo/Wood</name>
            <uri>file://media/materials/scripts/gazebo.material</uri>
          </script>
        </material>
      </visual>
      <gravity>1</gravity>
      <velocity_decay/>
      <self_collide>0</self_collide>
    </link>
    <joint name='rotor_2_joint' type='revolute'>
      <child>rotor_2</child>
      <parent>base_link</parent>
      <axis>
        <xyz>0 0 1</xyz>
        <limit>
          <lower>-1e+16</lower>
          <upper>1e+16</upper>
        </limit>
        <dynamics>
          <spring_reference>0</spring_reference>
          <spring_stiffness>0</spring_stiffness>
        </dynamics>
        <use_parent_model_frame>1</use_parent_model_frame>
      </axis>
    </joint>
<!--*********************************** rotor_3 *********************************-->
    <link name='rotor_3'>
      <pose>-0.078 -0.1 0 0 -0 0</pose>
      <inertial>
        <pose>0 0 0 0 -0 0</pose>
        <mass>0.005</mass>
        <inertia>
          <ixx>9.75e-07</ixx>
          <ixy>0</ixy>
          <ixz>0</ixz>
          <iyy>0.000273104</iyy>
          <iyz>0</iyz>
          <izz>0.000274004</izz>
        </inertia>
      </inertial>
      <collision name='rotor_3_collision'>
        <pose>0 0 0.076 0 -0 0</pose>
        <geometry>
          <cylinder>
            <length>0.01</length>
            <radius>0.064</radius>
          </cylinder>
        </geometry>
        <surface>
          <contact>
            <ode/>
          </contact>
          <friction>
            <ode/>
          </friction>
        </surface>
      </collision>
      <visual name='rotor_3_visual'>
        <pose>0 0 0.076 0 -0 0</pose>
        <geometry>
          <mesh>
            <scale>1 1 1</scale>
            <uri>model://mav_isir/meshes/propeller4.STL</uri>
          </mesh>
        </geometry>
        <material>
          <script>
            <name>Gazebo/Wood</name>
            <uri>file://media/materials/scripts/gazebo.material</uri>
          </script>
        </material>
      </visual>
      <gravity>1</gravity>
      <velocity_decay/>
      <self_collide>0</self_collide>
    </link>
    <joint name='rotor_3_joint' type='revolute'>
      <child>rotor_3</child>
      <parent>base_link</parent>
      <axis>
        <xyz>0 0 1</xyz>
        <limit>
          <lower>-1e+16</lower>
          <upper>1e+16</upper>
        </limit>
        <dynamics>
          <spring_reference>0</spring_reference>
          <spring_stiffness>0</spring_stiffness>
        </dynamics>
        <use_parent_model_frame>1</use_parent_model_frame>
      </axis>
    </joint>



<!--*********************************** pixhwak_autopilot_link *********************************-->
    <link name='imu_link'>
      <pose>-0.037 0 0.118 0 0 0</pose>
      <inertial>
        <pose>0 0 0 0 0 0</pose>
        <mass>0.015</mass>
        <inertia>
          <ixx>1e-05</ixx>
          <ixy>0</ixy>
          <ixz>0</ixz>
          <iyy>1e-05</iyy>
          <iyz>0</iyz>
          <izz>1e-05</izz>
        </inertia>
      </inertial>
    </link>
    <joint name='imu_joint' type='revolute'>
      <child>imu_link</child>
      <parent>base_link</parent>
      <axis>
        <xyz>1 0 0</xyz>
        <limit>
          <lower>0</lower>
          <upper>0</upper>
          <effort>0</effort>
          <velocity>0</velocity>
        </limit>
        <dynamics>
          <spring_reference>0</spring_reference>
          <spring_stiffness>0</spring_stiffness>
        </dynamics>
        <use_parent_model_frame>1</use_parent_model_frame>
      </axis>
    </joint>


<!--*********************************** gps_link *********************************-->
    <include>
      <uri>model://gps</uri>
      <pose>0.02 0 0.115 0 0 0</pose>
      <name>gps</name>
    </include>
    <joint name='gps_joint' type='fixed'>
      <child>gps::link</child>
      <parent>base_link</parent>
    </joint>



<!--*********************************** 3d_camera_link *********************************-->
<!--    <link name="depthcamera_link">-->
<!--      <pose>0.0809 0.0 0.104 0 0 0</pose>-->
<!--      <inertial>-->
<!--        <pose>0.0 0.0 0.0 0 0 0</pose>-->
<!--        <mass>0.001</mass>-->
<!--        <inertia>-->
<!--          <ixx>4.15e-6</ixx>-->
<!--          <ixy>0</ixy>-->
<!--          <ixz>0</ixz>-->
<!--          <iyy>2.407e-6</iyy>-->
<!--          <iyz>0</iyz>-->
<!--          <izz>2.407e-6</izz>-->
<!--        </inertia>-->
<!--      </inertial>-->
<!--      <collision name='3D_camera_collision'>-->
<!--        <pose>0 0 0.0067 0 -1.57079 -3.1415</pose>-->
<!--        <geometry>-->
<!--          <mesh>-->
<!--            <scale>1 1 1</scale>-->
<!--            <uri>model://mav_isir/meshes/3D_camera.STL</uri>-->
<!--          </mesh>-->
<!--        </geometry>-->
<!--      </collision>-->
<!--      <visual name='3D_camera_visual'>-->
<!--        <pose>0 0 0.0067 0 -1.57079 -3.1415</pose>-->
<!--        <geometry>-->
<!--          <mesh>-->
<!--            <scale>1 1 1</scale>-->
<!--            <uri>model://mav_isir/meshes/3D_camera.STL</uri>-->
<!--          </mesh>-->
<!--        </geometry>-->
<!--        <material>-->
<!--          <script>-->
<!--            <name>Gazebo/White</name>-->
<!--            <uri>file://media/materials/scripts/gazebo.material</uri>-->
<!--          </script>-->
<!--        </material>-->
<!--      </visual>-->
<!--      <sensor name="depth_camera" type="depth">-->
<!--        <always_on>true</always_on>-->
<!--        <update_rate>30</update_rate>-->
<!--        <visualize>true</visualize>-->
<!--        <camera>-->
<!--          <horizontal_fov>1.02974</horizontal_fov>-->
<!--          <image>-->
<!--            <format>R8G8B8</format>-->
<!--            <width>64</width>-->
<!--            <height>48</height>-->
<!--          </image>-->
<!--          <clip>-->
<!--            <near>0.5</near>-->
<!--            <far>18</far>-->
<!--          </clip>-->
<!--        </camera>-->
<!--        <plugin filename="libgazebo_ros_openni_kinect.so" name="camera_controller">-->
<!--          <robotNamespace></robotNamespace>-->
<!--          <cameraName>depth_camera</cameraName>-->
<!--          <alwaysOn>true</alwaysOn>-->
<!--          <updateRate>30</updateRate>-->
<!--          <pointCloudCutoff>0.2</pointCloudCutoff>-->
<!--          <pointCloudCutoffMax>20</pointCloudCutoffMax>-->
<!--          <imageTopicName>rgb/image_raw</imageTopicName>-->
<!--          <cameraInfoTopicName>rgb/camera_info</cameraInfoTopicName>-->
<!--          <depthImageTopicName>depth/image_raw</depthImageTopicName>-->
<!--          <depthImageCameraInfoTopicName>depth/camera_info</depthImageCameraInfoTopicName>-->
<!--          <pointCloudTopicName>depth/points</pointCloudTopicName>-->
<!--          <frameName>depth_camera_frame</frameName>-->
<!--          <pointCloudCutoff>0.5</pointCloudCutoff>-->
<!--          <pointCloudCutoffMax>3.0</pointCloudCutoffMax>-->
<!--          <distortion_k1>0.0</distortion_k1>-->
<!--          <distortion_k2>0.0</distortion_k2>-->
<!--          <distortion_k3>0.0</distortion_k3>-->
<!--          <distortion_t1>0.0</distortion_t1>-->
<!--          <distortion_t2>0.0</distortion_t2>-->
<!--        </plugin>-->
<!--      </sensor>-->
<!--    </link>-->
<!--    <joint name="depth_camera_joint" type="revolute">-->
<!--      <child>depthcamera_link</child>-->
<!--      <parent>base_link</parent>-->
<!--      <axis>-->
<!--        <xyz>0 0 1</xyz>-->
<!--        <limit>-->
<!--          <upper>0</upper>-->
<!--          <lower>0</lower>-->
<!--        </limit>-->
<!--      </axis>-->
<!--    </joint>-->


<!--*********************************** laser_downward_link *********************************-->
<!--    <link name="laser_downward_link">-->
<!--      <pose>0.02 0 0.021 0 0 0</pose>-->
<!--      <inertial>-->
<!--        <pose>0 0 0 0 0 0</pose>-->
<!--        <mass>0.01</mass>-->
<!--        <inertia>-->
<!--          <ixx>2.1733e-6</ixx>-->
<!--          <ixy>0</ixy>-->
<!--          <ixz>0</ixz>-->
<!--          <iyy>2.1733e-6</iyy>-->
<!--          <iyz>0</iyz>-->
<!--          <izz>1.8e-7</izz>-->
<!--        </inertia>-->
<!--      </inertial>-->
<!--      <collision name='laser_downward_link_collision'>-->
<!--      	<pose>0 0 0 -1.5707963259 0 1.5707963259</pose>-->
<!--        <geometry>-->
<!--          <mesh>-->
<!--            <scale>1 1 1</scale>-->
<!--            <uri>model://lidar/meshes/Tfmini_s.STL</uri>-->
<!--          </mesh>-->
<!--        </geometry>-->
<!--      </collision>-->
<!--      <visual name='laser_downward_link_visual'>-->
<!--      	<pose>0 0 0 -1.5707963259 0 1.5707963259</pose>-->
<!--        <geometry>-->
<!--          <mesh>-->
<!--            <scale>1 1 1</scale>-->
<!--            <uri>model://lidar/meshes/Tfmini_s.STL</uri>-->
<!--          </mesh>-->
<!--        </geometry>-->
<!--        <material>-->
<!--          <script>-->
<!--            <name>Gazebo/White</name>-->
<!--            <uri>file://media/materials/scripts/gazebo.material</uri>-->
<!--          </script>-->
<!--        </material>-->
<!--      </visual>-->
<!--      <sensor name="laser_downward" type="ray">-->
<!--        <always_on>1</always_on>-->
<!--        <update_rate>300</update_rate>-->
<!--        <visualize>true</visualize>-->
<!--        <pose>0 0 0 0 1.57079633 0</pose>-->
<!--        <ray>-->
<!--          <scan>-->
<!--            <horizontal>-->
<!--              <samples>1</samples>-->
<!--              <resolution>1</resolution>-->
<!--              <min_angle>-0.001</min_angle>-->
<!--              <max_angle>0.001</max_angle>-->
<!--            </horizontal>-->
<!--          </scan>-->
<!--          <range>-->
<!--            <min>0.3</min>-->
<!--            <max>12</max>-->
<!--            <resolution>0.01</resolution>-->
<!--          </range>-->
<!--          <noise>-->
<!--            <type>gaussian</type>-->
<!--            <mean>0.0</mean>-->
<!--            <stddev>0.06</stddev>-->
<!--          </noise>-->
<!--        </ray>-->
<!--        <plugin name="gazebo_ros_laser_downward_controller" filename="libgazebo_ros_laser.so">-->
<!--          <robotNamespace></robotNamespace>-->
<!--          <topicName>laser_downward/scan</topicName>-->
<!--          <frameName>laser_downward_frame</frameName>-->
<!--        </plugin>-->
<!--      </sensor>-->
<!--    </link>-->
<!--    <joint name="laser_downward_joint" type="fixed">-->
<!--      <parent>base_link</parent>-->
<!--      <child>laser_downward_link</child>-->
<!--    </joint>-->


<!--*********************************** laser_upward_link *********************************-->
<!--    <link name="laser_upward_link">-->
<!--      <pose>0.013208 0 0.1187 0 0 0</pose>-->
<!--      <inertial>-->
<!--        <pose>0 0 0 0 0 0</pose>-->
<!--        <mass>0.001</mass>-->
<!--        <inertia>-->
<!--          <ixx>2.1733e-6</ixx>-->
<!--          <ixy>0</ixy>-->
<!--          <ixz>0</ixz>-->
<!--          <iyy>2.1733e-6</iyy>-->
<!--          <iyz>0</iyz>-->
<!--          <izz>1.8e-7</izz>-->
<!--        </inertia>-->
<!--      </inertial>-->
<!--      <collision name='laser_upward_link_collision'>-->
<!--        <pose>0 0 0 1.5708 -0 1.5708</pose>-->
<!--        <geometry>-->
<!--          <mesh>-->
<!--            <scale>1 1 1</scale>-->
<!--            <uri>model://mav_isir/meshes/Laser_up.STL</uri>-->
<!--          </mesh>-->
<!--        </geometry>-->
<!--      </collision>-->
<!--      <visual name='laser_upward_link_visual'>-->
<!--        <pose>0 0 0 1.5708 -0 1.5708</pose>-->
<!--        <geometry>-->
<!--          <mesh>-->
<!--            <scale>1 1 1</scale>-->
<!--            <uri>model://mav_isir/meshes/Laser_up.STL</uri>-->
<!--          </mesh>-->
<!--        </geometry>-->
<!--        <material>-->
<!--          <script>-->
<!--            <name>Gazebo/White</name>-->
<!--            <uri>file://media/materials/scripts/gazebo.material</uri>-->
<!--          </script>-->
<!--        </material>-->
<!--      </visual>-->
<!--      <sensor name="laser_upward" type="ray">-->
<!--        <pose>0 0 0 1.5708 -1.5708 1.5708</pose>-->
<!--        <always_on>1</always_on>-->
<!--        <update_rate>300</update_rate>-->
<!--        <visualize>true</visualize>-->
<!--        <ray>-->
<!--          <scan>-->
<!--            <horizontal>-->
<!--              <samples>1</samples>-->
<!--              <resolution>1</resolution>-->
<!--              <min_angle>-0.001</min_angle>-->
<!--              <max_angle>0.001</max_angle>-->
<!--            </horizontal>-->
<!--          </scan>-->
<!--          <range>-->
<!--            <min>0.1</min>-->
<!--            <max>12</max>-->
<!--            <resolution>0.01</resolution>-->
<!--          </range>-->
<!--          <noise>-->
<!--            <type>gaussian</type>-->
<!--            <mean>0.0</mean>-->
<!--            <stddev>0.06</stddev>-->
<!--          </noise>-->
<!--        </ray>-->
<!--        <plugin name="gazebo_ros_laser_upward_controller" filename="libgazebo_ros_laser.so">-->
<!--          <robotNamespace></robotNamespace>-->
<!--          <topicName>laser_upward/scan</topicName>-->
<!--          <frameName>laser_upward_frame</frameName>-->
<!--        </plugin>-->
<!--      </sensor>-->
<!--    </link>-->
<!--    <joint name="laser_upward_joint" type="fixed">-->
<!--      <parent>base_link</parent>-->
<!--      <child>laser_upward_link</child>-->
<!--    </joint>-->





<!--*********************************** laser_hor_link *********************************-->
<!--    <link name="laser_hor_link">-->
<!--      <pose>0 0 0 0 0 0</pose>-->
<!--      <inertial>-->
<!--        <pose>0 0 0 0 0 0</pose>-->
<!--        <mass>0.001</mass>-->
<!--        <inertia>-->
<!--          <ixx>2.1733e-6</ixx>-->
<!--          <ixy>0</ixy>-->
<!--          <ixz>0</ixz>-->
<!--          <iyy>2.1733e-6</iyy>-->
<!--          <iyz>0</iyz>-->
<!--          <izz>1.8e-7</izz>-->
<!--        </inertia>-->
<!--      </inertial>-->
	<!-- laser_front_right_link -->
<!--      <collision name='laser_front_right_link_collision'>-->
<!--        <pose>0.018738 -0.018738 0.0485 0 2.35619 -2.35619</pose>-->
<!--        <geometry>-->
<!--          <mesh>-->
<!--            <scale>1 1 1</scale>-->
<!--            <uri>model://mav_isir/meshes/Laser_1.STL</uri>-->
<!--          </mesh>-->
<!--        </geometry>-->
<!--      </collision>-->
<!--      <visual name='laser_front_right_link_visual'>-->
<!--        <pose>0.018738 -0.018738 0.0485 0 2.35619 -2.35619</pose>-->
<!--        <geometry>-->
<!--          <mesh>-->
<!--            <scale>1 1 1</scale>-->
<!--            <uri>model://mav_isir/meshes/Laser_1.STL</uri>-->
<!--          </mesh>-->
<!--        </geometry>-->
<!--        <material>-->
<!--          <script>-->
<!--            <name>Gazebo/White</name>-->
<!--            <uri>file://media/materials/scripts/gazebo.material</uri>-->
<!--          </script>-->
<!--        </material>-->
<!--      </visual>-->
	<!-- laser_back_right_link -->
<!--      <collision name='laser_back_right_link_collision'>-->
<!--        <pose>-0.018686 -0.018791 0.048575 0 3.92699 2.35619</pose>-->
<!--        <geometry>-->
<!--          <mesh>-->
<!--            <scale>1 1 1</scale>-->
<!--            <uri>model://mav_isir/meshes/Laser_2.STL</uri>-->
<!--          </mesh>-->
<!--        </geometry>-->
<!--      </collision>-->
<!--      <visual name='laser_back_right_link_visual'>-->
<!--        <pose>-0.018686 -0.018791 0.048575 0 3.92699 2.35619</pose>-->
<!--        <geometry>-->
<!--          <mesh>-->
<!--            <scale>1 1 1</scale>-->
<!--            <uri>model://mav_isir/meshes/Laser_2.STL</uri>-->
<!--          </mesh>-->
<!--        </geometry>-->
<!--        <material>-->
<!--          <script>-->
<!--            <name>Gazebo/White</name>-->
<!--            <uri>file://media/materials/scripts/gazebo.material</uri>-->
<!--          </script>-->
<!--        </material>-->
<!--      </visual>-->
	<!-- laser_back_left_link -->
<!--      <collision name='laser_back_left_link_collision'>-->
<!--        <pose>-0.018897 0.018791 0.048575 -0 -3.92699 0.779523</pose>-->
<!--        <geometry>-->
<!--          <mesh>-->
<!--            <scale>1 1 1</scale>-->
<!--            <uri>model://mav_isir/meshes/Laser_3.STL</uri>-->
<!--          </mesh>-->
<!--        </geometry>-->
<!--      </collision>-->
<!--      <visual name='laser_back_left_link_visual'>-->
<!--        <pose>-0.018897 0.018791 0.048575 -0 -3.92699 0.779523</pose>-->
<!--        <geometry>-->
<!--          <mesh>-->
<!--            <scale>1 1 1</scale>-->
<!--            <uri>model://mav_isir/meshes/Laser_3.STL</uri>-->
<!--          </mesh>-->
<!--        </geometry>-->
<!--        <material>-->
<!--          <script>-->
<!--            <name>Gazebo/White</name>-->
<!--            <uri>file://media/materials/scripts/gazebo.material</uri>-->
<!--          </script>-->
<!--        </material>-->
<!--      </visual>-->
	<!-- laser_front_left_link -->
<!--      <collision name='laser_front_left_collision'>-->
<!--        <pose>0.018949 0.018738 0.0485 -0 -2.35619 -0.785398</pose>-->
<!--        <geometry>-->
<!--          <mesh>-->
<!--            <scale>1 1 1</scale>-->
<!--            <uri>model://mav_isir/meshes/Laser_4.STL</uri>-->
<!--          </mesh>-->
<!--        </geometry>-->
<!--      </collision>-->
<!--      <visual name='laser_front_left_visual'>-->
<!--        <pose>0.018949 0.018738 0.0485 -0 -2.35619 -0.785398</pose>-->
<!--        <geometry>-->
<!--          <mesh>-->
<!--            <scale>1 1 1</scale>-->
<!--            <uri>model://mav_isir/meshes/Laser_4.STL</uri>-->
<!--          </mesh>-->
<!--        </geometry>-->
<!--        <material>-->
<!--          <script>-->
<!--            <name>Gazebo/White</name>-->
<!--            <uri>file://media/materials/scripts/gazebo.material</uri>-->
<!--          </script>-->
<!--        </material>-->
<!--      </visual>-->

<!--      <sensor name="laser_hor" type="ray">-->
<!--        <pose>0 0 0.0485 0 0 0.785398</pose>-->
<!--        <always_on>1</always_on>-->
<!--        <update_rate>1000</update_rate>-->
<!--        <visualize>true</visualize>-->
<!--        <ray>-->
<!--          <scan>-->
<!--            <horizontal>-->
<!--              <samples>4</samples>-->
<!--              <resolution>1</resolution>-->
<!--              <min_angle>0</min_angle>-->
<!--              <max_angle>4.71238898</max_angle>-->
<!--            </horizontal>-->
<!--          </scan>-->
<!--          <range>-->
<!--            <min>0.1</min>-->
<!--            <max>12</max>-->
<!--            <resolution>0.01</resolution>-->
<!--          </range>-->
<!--          <noise>-->
<!--            <type>gaussian</type>-->
<!--            <mean>0.0</mean>-->
<!--            <stddev>0.06</stddev>-->
<!--          </noise>-->
<!--        </ray>-->
<!--        <plugin name="gazebo_ros_laser_hor_controller" filename="libgazebo_ros_laser.so">-->
<!--          <robotNamespace></robotNamespace>-->
<!--          <topicName>laser_hor/scan</topicName>-->
<!--          <frameName>laser_hor_frame</frameName>-->
<!--        </plugin>-->
<!--      </sensor>-->
<!--    </link>-->
<!--    <joint name="laser_hor_joint" type="fixed">-->
<!--      <parent>base_link</parent>-->
<!--      <child>laser_hor_link</child>-->
<!--    </joint>-->



<!--*********************************** others plugin *********************************-->
    <plugin name='rosbag' filename='libgazebo_multirotor_base_plugin.so'>
      <robotNamespace></robotNamespace>
      <linkName>base_link</linkName>
      <rotorVelocitySlowdownSim>10</rotorVelocitySlowdownSim>
    </plugin>
    <plugin name='front_right_motor_model' filename='libgazebo_motor_model.so'>
      <robotNamespace></robotNamespace>
      <jointName>rotor_0_joint</jointName>
      <linkName>rotor_0</linkName>
      <turningDirection>ccw</turningDirection>
      <timeConstantUp>0.0125</timeConstantUp>
      <timeConstantDown>0.025</timeConstantDown>
      <maxRotVelocity>1500</maxRotVelocity>
      <motorConstant>8.54858e-06</motorConstant>
      <momentConstant>0.06</momentConstant>
      <commandSubTopic>/gazebo/command/motor_speed</commandSubTopic>
      <motorNumber>0</motorNumber>
      <rotorDragCoefficient>0.000806428</rotorDragCoefficient>
      <rollingMomentCoefficient>1e-06</rollingMomentCoefficient>
      <motorSpeedPubTopic>/motor_speed/0</motorSpeedPubTopic>
      <rotorVelocitySlowdownSim>10</rotorVelocitySlowdownSim>
    </plugin>
    <plugin name='back_left_motor_model' filename='libgazebo_motor_model.so'>
      <robotNamespace></robotNamespace>
      <jointName>rotor_1_joint</jointName>
      <linkName>rotor_1</linkName>
      <turningDirection>ccw</turningDirection>
      <timeConstantUp>0.0125</timeConstantUp>
      <timeConstantDown>0.025</timeConstantDown>
      <maxRotVelocity>1500</maxRotVelocity>
      <motorConstant>8.54858e-06</motorConstant>
      <momentConstant>0.06</momentConstant>
      <commandSubTopic>/gazebo/command/motor_speed</commandSubTopic>
      <motorNumber>1</motorNumber>
      <rotorDragCoefficient>0.000806428</rotorDragCoefficient>
      <rollingMomentCoefficient>1e-06</rollingMomentCoefficient>
      <motorSpeedPubTopic>/motor_speed/1</motorSpeedPubTopic>
      <rotorVelocitySlowdownSim>10</rotorVelocitySlowdownSim>
    </plugin>
    <plugin name='front_left_motor_model' filename='libgazebo_motor_model.so'>
      <robotNamespace></robotNamespace>
      <jointName>rotor_2_joint</jointName>
      <linkName>rotor_2</linkName>
      <turningDirection>cw</turningDirection>
      <timeConstantUp>0.0125</timeConstantUp>
      <timeConstantDown>0.025</timeConstantDown>
      <maxRotVelocity>1500</maxRotVelocity>
      <motorConstant>8.54858e-06</motorConstant>
      <momentConstant>0.06</momentConstant>
      <commandSubTopic>/gazebo/command/motor_speed</commandSubTopic>
      <motorNumber>2</motorNumber>
      <rotorDragCoefficient>0.000806428</rotorDragCoefficient>
      <rollingMomentCoefficient>1e-06</rollingMomentCoefficient>
      <motorSpeedPubTopic>/motor_speed/2</motorSpeedPubTopic>
      <rotorVelocitySlowdownSim>10</rotorVelocitySlowdownSim>
    </plugin>
    <plugin name='back_right_motor_model' filename='libgazebo_motor_model.so'>
      <robotNamespace></robotNamespace>
      <jointName>rotor_3_joint</jointName>
      <linkName>rotor_3</linkName>
      <turningDirection>cw</turningDirection>
      <timeConstantUp>0.0125</timeConstantUp>
      <timeConstantDown>0.025</timeConstantDown>
      <maxRotVelocity>1500</maxRotVelocity>
      <motorConstant>8.54858e-06</motorConstant>
      <momentConstant>0.06</momentConstant>
      <commandSubTopic>/gazebo/command/motor_speed</commandSubTopic>
      <motorNumber>3</motorNumber>
      <rotorDragCoefficient>0.000806428</rotorDragCoefficient>
      <rollingMomentCoefficient>1e-06</rollingMomentCoefficient>
      <motorSpeedPubTopic>/motor_speed/3</motorSpeedPubTopic>
      <rotorVelocitySlowdownSim>10</rotorVelocitySlowdownSim>
    </plugin>

    <!-- PUB Ground Truth -->
    <plugin name='groundtruth_plugin' filename='libgazebo_groundtruth_plugin.so'>
      <robotNamespace/>
    </plugin>
    <plugin name='magnetometer_plugin' filename='libgazebo_magnetometer_plugin.so'>
      <robotNamespace/>
      <pubRate>100</pubRate>
      <noiseDensity>0.0004</noiseDensity>
      <randomWalk>6.4e-06</randomWalk>
      <biasCorrelationTime>600</biasCorrelationTime>
      <magTopic>/mag</magTopic>
    </plugin>
    <plugin name='barometer_plugin' filename='libgazebo_barometer_plugin.so'>
      <robotNamespace/>
      <pubRate>50</pubRate>
      <baroTopic>/baro</baroTopic>
    </plugin>
    <plugin name='mavlink_interface' filename='libgazebo_mavlink_interface.so'>
      <robotNamespace/>
      <imuSubTopic>/imu</imuSubTopic>
      <gpsSubTopic>/gps</gpsSubTopic>
      <magSubTopic>/mag</magSubTopic>
      <baroSubTopic>/baro</baroSubTopic>
      <mavlink_addr>INADDR_ANY</mavlink_addr>
      <mavlink_tcp_port>4560</mavlink_tcp_port>
      <mavlink_udp_port>14560</mavlink_udp_port>
      <serialEnabled>false</serialEnabled>
      <serialDevice>/dev/ttyACM0</serialDevice>
      <baudRate>921600</baudRate>
      <qgc_addr>INADDR_ANY</qgc_addr>
      <qgc_udp_port>14550</qgc_udp_port>
      <hil_mode>false</hil_mode>
      <hil_state_level>false</hil_state_level>
      <enable_lockstep>true</enable_lockstep>
      <use_tcp>true</use_tcp>
      <motorSpeedCommandPubTopic>/gazebo/command/motor_speed</motorSpeedCommandPubTopic>
      <control_channels>
        <channel name='rotor1'>
          <input_index>0</input_index>
          <input_offset>0</input_offset>
          <input_scaling>1000</input_scaling>
          <zero_position_disarmed>0</zero_position_disarmed>
          <zero_position_armed>100</zero_position_armed>
          <joint_control_type>velocity</joint_control_type>
        </channel>
        <channel name='rotor2'>
          <input_index>1</input_index>
          <input_offset>0</input_offset>
          <input_scaling>1000</input_scaling>
          <zero_position_disarmed>0</zero_position_disarmed>
          <zero_position_armed>100</zero_position_armed>
          <joint_control_type>velocity</joint_control_type>
        </channel>
        <channel name='rotor3'>
          <input_index>2</input_index>
          <input_offset>0</input_offset>
          <input_scaling>1000</input_scaling>
          <zero_position_disarmed>0</zero_position_disarmed>
          <zero_position_armed>100</zero_position_armed>
          <joint_control_type>velocity</joint_control_type>
        </channel>
        <channel name='rotor4'>
          <input_index>3</input_index>
          <input_offset>0</input_offset>
          <input_scaling>1000</input_scaling>
          <zero_position_disarmed>0</zero_position_disarmed>
          <zero_position_armed>100</zero_position_armed>
          <joint_control_type>velocity</joint_control_type>
        </channel>
      </control_channels>
    </plugin>
    <static>0</static>
    <plugin name='gazebo_imu_plugin' filename='libgazebo_imu_plugin.so'>
      <robotNamespace></robotNamespace>
      <linkName>imu_link</linkName>
      <imuTopic>/imu</imuTopic>
      <gyroscopeNoiseDensity>0.00018665</gyroscopeNoiseDensity>
      <gyroscopeRandomWalk>3.8785e-05</gyroscopeRandomWalk>
      <gyroscopeBiasCorrelationTime>1000.0</gyroscopeBiasCorrelationTime>
      <gyroscopeTurnOnBiasSigma>0.0087</gyroscopeTurnOnBiasSigma>
      <accelerometerNoiseDensity>0.00186</accelerometerNoiseDensity>
      <accelerometerRandomWalk>0.006</accelerometerRandomWalk>
      <accelerometerBiasCorrelationTime>300.0</accelerometerBiasCorrelationTime>
      <accelerometerTurnOnBiasSigma>0.196</accelerometerTurnOnBiasSigma>
    </plugin>
    <!-- plugins: libgazebo_ros_p3d -->
    <!-- 发布真值,模拟vicon系统 -->
    <plugin name="p3d_base_controller" filename="libgazebo_ros_p3d.so">
      <robotNamespace/>
      <alwaysOn>true</alwaysOn>
      <updateRate>50.0</updateRate>
      <bodyName>base_link</bodyName>
      <topicName>drone_msg/ground_truth/odometry</topicName>
      <gaussianNoise>0.00</gaussianNoise>
      <frameName>world</frameName>
      <xyzOffsets>0 0 0</xyzOffsets>
      <rpyOffsets>0 0 0</rpyOffsets>
    </plugin>
  </model>
</sdf>
